[85888] -Framework Log- 2024-02-22 16:50:43 | ERROR | connect_async.py:57: asyncio.run() cannot be called from a running event loop[0m
[86269] -Framework Log- 2024-02-22 16:57:01 | ERROR | connect_async.py:57: asyncio.run() cannot be called from a running event loop[0m
[86377] -Framework Log- 2024-02-22 16:58:37 | ERROR | connect_async.py:57: asyncio.run() cannot be called from a running event loop[0m
[86609] -Framework Log- 2024-02-22 17:02:44 | ERROR | connect_async.py:57: This event loop is already running[0m
[86662] -Framework Log- 2024-02-22 17:03:40 | ERROR | connect_async.py:57: This event loop is already running[0m
[0] [31m[PID17239] -Framework Log- 2024-09-23 11:23:06 | ERROR | connect.py:65: Error initializing Redis client: Redis Cluster cannot be connected. Please provide at least one reachable node: "max_connections" must be a positive integer[0m
[0] [32m[PID17378] -Framework Log- 2024-09-23 11:24:45 | INFO | connect.py:83: Redis connection established.[0m
[0] [32m[PID17378] -Framework Log- 2024-09-23 11:24:45 | INFO | connect.py:97: Redis connection closed.[0m
[0] [32m[PID17451] -Framework Log- 2024-09-23 11:25:54 | INFO | connect.py:83: Redis connection established.[0m
[0] [31m[PID17451] -Framework Log- 2024-09-23 11:25:54 | ERROR | connect_async.py:64: Error initializing Redis client: asyncio.run() cannot be called from a running event loop[0m
[0] [31m[PID17451] -Framework Log- 2024-09-23 11:25:54 | ERROR | __init__.py:65: Redis connect error: asyncio.run() cannot be called from a running event loop[0m
[0] [32m[PID17543] -Framework Log- 2024-09-23 11:27:48 | INFO | connect.py:83: Redis connection established.[0m
[0] [31m[PID17543] -Framework Log- 2024-09-23 11:27:48 | ERROR | __init__.py:65: Redis connect error: asyncio.run() cannot be called from a running event loop[0m
[0] [32m[PID17721] -Framework Log- 2024-09-23 11:31:02 | INFO | connect.py:83: Redis connection established.[0m
[0] [31m[PID17721] -Framework Log- 2024-09-23 11:31:02 | ERROR | __init__.py:65: Redis connect error: asyncio.run() cannot be called from a running event loop[0m
[0] [32m[PID17809] -Framework Log- 2024-09-23 11:32:06 | INFO | connect.py:83: Redis connection established.[0m
[0] [32m[PID18022] -Framework Log- 2024-09-23 11:34:10 | INFO | connect.py:83: Redis connection established.[0m
